
Traceback (most recent call last):
  File "phantom.py", line 16, in main
    main.start()
  File "src/main.py", line 419, in start
    actions.call(config.action, action_kwargs)
  File "src/main.py", line 116, in call
    func(**kwargs)
  File "src/main.py", line 123, in main
    from Ui import UiServer
  File "src/Ui/__init__.py", line 1, in <module>
    from UiServer import UiServer
  File "src/Ui/UiServer.py", line 16, in <module>
    from Phantom import Phantom_Ui
  File "src/Phantom/Phantom_Ui.py", line 481
    def run(postdata):
                     ^
IndentationError: unexpected unindent
Traceback (most recent call last):
  File "phantom.py", line 16, in main
    main.start()
  File "src/main.py", line 419, in start
    actions.call(config.action, action_kwargs)
  File "src/main.py", line 116, in call
    func(**kwargs)
  File "src/main.py", line 123, in main
    from Ui import UiServer
  File "src/Ui/__init__.py", line 1, in <module>
    from UiServer import UiServer
  File "src/Ui/UiServer.py", line 16, in <module>
    from Phantom import Phantom_Ui
  File "src/Phantom/Phantom_Ui.py", line 480
    response[pos] = (values['date'] = i[0])
                                    ^
SyntaxError: invalid syntax
Traceback (most recent call last):
  File "phantom.py", line 16, in main
    main.start()
  File "src/main.py", line 419, in start
    actions.call(config.action, action_kwargs)
  File "src/main.py", line 116, in call
    func(**kwargs)
  File "src/main.py", line 123, in main
    from Ui import UiServer
  File "src/Ui/__init__.py", line 1, in <module>
    from UiServer import UiServer
  File "src/Ui/UiServer.py", line 16, in <module>
    from Phantom import Phantom_Ui
  File "src/Phantom/Phantom_Ui.py", line 479
    response[pos] = {'date' : i[0], 'from' : i[1], 'to' = i[2], 'amount' = i[3]}
                                                        ^
SyntaxError: invalid syntax
Traceback (most recent call last):
  File "phantom.py", line 15, in main
    import main
  File "src/main.py", line 6, in <module>
    from Phantom import Phantom_Db
  File "src/Phantom/Phantom_Db.py", line 5, in <module>
    class PhantomDb(object):
  File "src/Phantom/Phantom_Db.py", line 7, in PhantomDb
    conn_phantom = sqlite3.conn_phantomect('src/Phantom/phantom.db')
AttributeError: 'module' object has no attribute 'conn_phantomect'
Traceback (most recent call last):
  File "phantom.py", line 15, in main
    import main
  File "src/main.py", line 6, in <module>
    from Phantom import Phantom_Db
  File "src/Phantom/Phantom_Db.py", line 118
    ecept Exception as e:
        ^
SyntaxError: invalid syntax
Traceback (most recent call last):
  File "phantom.py", line 16, in main
    main.start()
  File "src/main.py", line 419, in start
    actions.call(config.action, action_kwargs)
  File "src/main.py", line 116, in call
    func(**kwargs)
  File "src/main.py", line 123, in main
    from Ui import UiServer
  File "src/Ui/__init__.py", line 1, in <module>
    from UiServer import UiServer
  File "src/Ui/UiServer.py", line 16, in <module>
    from Phantom import Phantom_Ui
  File "src/Phantom/Phantom_Ui.py", line 570
    except Exception as e:
         ^
SyntaxError: invalid syntax
Traceback (most recent call last):
  File "phantom.py", line 16, in main
    main.start()
  File "src/main.py", line 419, in start
    actions.call(config.action, action_kwargs)
  File "src/main.py", line 116, in call
    func(**kwargs)
  File "src/main.py", line 128, in main
    ui_server = UiServer()
  File "src/Ui/UiServer.py", line 70, in __init__
    self.gshift_process = Run_Gshift.start()
AttributeError: 'module' object has no attribute 'start'
Traceback (most recent call last):
  File "phantom.py", line 16, in main
    main.start()
  File "src/main.py", line 419, in start
    actions.call(config.action, action_kwargs)
  File "src/main.py", line 116, in call
    func(**kwargs)
  File "src/main.py", line 128, in main
    ui_server = UiServer()
  File "src/Ui/UiServer.py", line 71, in __init__
    self.gshift_process = gshift.start()
NameError: global name 'gshift' is not defined
Traceback (most recent call last):
  File "phantom.py", line 16, in main
    main.start()
  File "src/main.py", line 419, in start
    actions.call(config.action, action_kwargs)
  File "src/main.py", line 116, in call
    func(**kwargs)
  File "src/main.py", line 177, in siteSign
    site = Site(address, allow_create=False)
  File "src/Site/Site.py", line 52, in __init__
    self.loadSettings()  # Load settings from sites.json
  File "src/Site/Site.py", line 79, in loadSettings
    sites_settings = json.load(open("%s/sites.json" % config.data_dir))
  File "/usr/lib/python2.7/json/__init__.py", line 290, in load
    **kw)
  File "/usr/lib/python2.7/json/__init__.py", line 338, in loads
    return _default_decoder.decode(s)
  File "/usr/lib/python2.7/json/decoder.py", line 366, in decode
    obj, end = self.raw_decode(s, idx=_w(s, 0).end())
  File "/usr/lib/python2.7/json/decoder.py", line 384, in raw_decode
    raise ValueError("No JSON object could be decoded")
ValueError: No JSON object could be decoded
Traceback (most recent call last):
  File "phantom.py", line 16, in main
    main.start()
  File "src/main.py", line 419, in start
    actions.call(config.action, action_kwargs)
  File "src/main.py", line 116, in call
    func(**kwargs)
  File "src/main.py", line 128, in main
    ui_server = UiServer()
  File "src/Ui/UiServer.py", line 67, in __init__
    self.sites = SiteManager.site_manager.list()
  File "src/Site/SiteManager.py", line 90, in list
    self.load()
  File "src/Site/SiteManager.py", line 25, in load
    for address in json.load(open("%s/sites.json" % config.data_dir)):
  File "/usr/lib/python2.7/json/__init__.py", line 290, in load
    **kw)
  File "/usr/lib/python2.7/json/__init__.py", line 338, in loads
    return _default_decoder.decode(s)
  File "/usr/lib/python2.7/json/decoder.py", line 366, in decode
    obj, end = self.raw_decode(s, idx=_w(s, 0).end())
  File "/usr/lib/python2.7/json/decoder.py", line 384, in raw_decode
    raise ValueError("No JSON object could be decoded")
ValueError: No JSON object could be decoded
Traceback (most recent call last):
  File "phantom.py", line 16, in main
    main.start()
  File "src/main.py", line 419, in start
    actions.call(config.action, action_kwargs)
  File "src/main.py", line 116, in call
    func(**kwargs)
  File "src/main.py", line 123, in main
    from Ui import UiServer
  File "src/Ui/__init__.py", line 1, in <module>
    from UiServer import UiServer
  File "src/Ui/UiServer.py", line 16, in <module>
    from Phantom import Phantom_Ui
  File "src/Phantom/Phantom_Ui.py", line 204
    self.success = site.content_manager.sign(self.inner_path, self.privatekey=privatekey, uself.pdate_changed_files=True)
SyntaxError: keyword can't be an expression
Traceback (most recent call last):
  File "phantom.py", line 16, in main
    main.start()
  File "src/main.py", line 419, in start
    actions.call(config.action, action_kwargs)
  File "src/main.py", line 116, in call
    func(**kwargs)
  File "src/main.py", line 123, in main
    from Ui import UiServer
  File "src/Ui/__init__.py", line 1, in <module>
    from UiServer import UiServer
  File "src/Ui/UiServer.py", line 16, in <module>
    from Phantom import Phantom_Ui
  File "src/Phantom/Phantom_Ui.py", line 204
    self.success = site.content_manager.sign(self.inner_path, self.privatekey=privatekey, update_changed_files=True)
SyntaxError: keyword can't be an expression
Traceback (most recent call last):
  File "phantom.py", line 16, in main
    main.start()
  File "src/main.py", line 419, in start
    actions.call(config.action, action_kwargs)
  File "src/main.py", line 116, in call
    func(**kwargs)
  File "src/main.py", line 123, in main
    from Ui import UiServer
  File "src/Ui/__init__.py", line 1, in <module>
    from UiServer import UiServer
  File "src/Ui/UiServer.py", line 16, in <module>
    from Phantom import Phantom_Ui
  File "src/Phantom/Phantom_Ui.py", line 19, in <module>
    import Run_Method
  File "src/Phantom/Run_Method.py", line 4
    class Run_Method(object)
                           ^
SyntaxError: invalid syntax
Traceback (most recent call last):
  File "phantom.py", line 16, in main
    main.start()
  File "src/main.py", line 419, in start
    actions.call(config.action, action_kwargs)
  File "src/main.py", line 116, in call
    func(**kwargs)
  File "src/main.py", line 123, in main
    from Ui import UiServer
  File "src/Ui/__init__.py", line 1, in <module>
    from UiServer import UiServer
  File "src/Ui/UiServer.py", line 16, in <module>
    from Phantom import Phantom_Ui
  File "src/Phantom/Phantom_Ui.py", line 19, in <module>
    import Run_Method
  File "src/Phantom/Run_Method.py", line 1, in <module>
    import self.phantom_ui
ImportError: No module named self.phantom_ui
Traceback (most recent call last):
  File "phantom.py", line 16, in main
    main.start()
  File "src/main.py", line 419, in start
    actions.call(config.action, action_kwargs)
  File "src/main.py", line 116, in call
    func(**kwargs)
  File "src/main.py", line 123, in main
    from Ui import UiServer
  File "src/Ui/__init__.py", line 1, in <module>
    from UiServer import UiServer
  File "src/Ui/UiServer.py", line 16, in <module>
    from Phantom import Phantom_Ui
  File "src/Phantom/Phantom_Ui.py", line 19, in <module>
    import self.run_method
ImportError: No module named self.run_method
Traceback (most recent call last):
  File "phantom.py", line 16, in main
    main.start()
  File "src/main.py", line 419, in start
    actions.call(config.action, action_kwargs)
  File "src/main.py", line 116, in call
    func(**kwargs)
  File "src/main.py", line 123, in main
    from Ui import UiServer
  File "src/Ui/__init__.py", line 1, in <module>
    from UiServer import UiServer
  File "src/Ui/UiServer.py", line 16, in <module>
    from Phantom import Phantom_Ui
  File "src/Phantom/Phantom_Ui.py", line 19, in <module>
    import Run_Method
  File "src/Phantom/Run_Method.py", line 115
    return error_response..error_response("no_method")
                          ^
SyntaxError: invalid syntax
Traceback (most recent call last):
  File "phantom.py", line 16, in main
    main.start()
  File "src/main.py", line 419, in start
    actions.call(config.action, action_kwargs)
  File "src/main.py", line 116, in call
    func(**kwargs)
  File "src/main.py", line 123, in main
    from Ui import UiServer
  File "src/Ui/__init__.py", line 1, in <module>
    from UiServer import UiServer
  File "src/Ui/UiServer.py", line 16, in <module>
    from Phantom import Phantom_Ui
  File "src/Phantom/Phantom_Ui.py", line 19, in <module>
    import Run_Method
  File "src/Phantom/Run_Method.py", line 1, in <module>
    import self.phantom_ui
ImportError: No module named self.phantom_ui
Traceback (most recent call last):
  File "phantom.py", line 16, in main
    main.start()
  File "src/main.py", line 419, in start
    actions.call(config.action, action_kwargs)
  File "src/main.py", line 116, in call
    func(**kwargs)
  File "src/main.py", line 123, in main
    from Ui import UiServer
  File "src/Ui/__init__.py", line 1, in <module>
    from UiServer import UiServer
  File "src/Ui/UiServer.py", line 16, in <module>
    from Phantom import Phantom_Ui
  File "src/Phantom/Phantom_Ui.py", line 19, in <module>
    import Run_Method
  File "src/Phantom/Run_Method.py", line 1, in <module>
    import self.phantom_ui
ImportError: No module named self.phantom_ui
Traceback (most recent call last):
  File "phantom.py", line 16, in main
    main.start()
  File "src/main.py", line 419, in start
    actions.call(config.action, action_kwargs)
  File "src/main.py", line 116, in call
    func(**kwargs)
  File "src/main.py", line 123, in main
    from Ui import UiServer
  File "src/Ui/__init__.py", line 1, in <module>
    from UiServer import UiServer
  File "src/Ui/UiServer.py", line 16, in <module>
    from Phantom import Phantom_Ui
  File "src/Phantom/Phantom_Ui.py", line 19, in <module>
    import Run_Method
  File "src/Phantom/Run_Method.py", line 1, in <module>
    import self.phantom_ui
ImportError: No module named self.phantom_ui
Traceback (most recent call last):
  File "phantom.py", line 15, in main
    import main
  File "src/main.py", line 6, in <module>
    from Phantom import Phantom_Db
  File "src/Phantom/Phantom_Db.py", line 2, in <module>
    from Shift_IPC import IPC_Client
  File "src/Shift_IPC/IPC_Client.py", line 129
    static_nodes_string = '["enode://4c8635f108dae8a997697d9c22ddca36969e7f9bc57d9fc01102d7e7d9633231331ae7f7307aceb1aa19130b5bdd4afe397db616c76e7ffc1c69302ba0d09a39@45.32.182.61:53900",' +
                                                                                                                                                                                            ^
SyntaxError: invalid syntax
Traceback (most recent call last):
  File "phantom.py", line 15, in main
    import main
  File "src/main.py", line 6, in <module>
    from Phantom import Phantom_Db
  File "src/Phantom/Phantom_Db.py", line 2, in <module>
    from Shift_IPC import IPC_Client
  File "src/Shift_IPC/IPC_Client.py", line 132
    filepath = self.get_default_node_path()
           ^
SyntaxError: invalid syntax
Traceback (most recent call last):
  File "phantom.py", line 15, in main
    import main
  File "src/main.py", line 6, in <module>
    from Phantom import Phantom_Db
  File "src/Phantom/Phantom_Db.py", line 2, in <module>
    from Shift_IPC import IPC_Client
  File "src/Shift_IPC/IPC_Client.py", line 132
    self.filepath = self.get_default_node_path()
       ^
SyntaxError: invalid syntax
Traceback (most recent call last):
  File "phantom.py", line 15, in main
    import main
  File "src/main.py", line 6, in <module>
    from Phantom import Phantom_Db
  File "src/Phantom/Phantom_Db.py", line 2, in <module>
    from Shift_IPC import IPC_Client
  File "src/Shift_IPC/IPC_Client.py", line 132
    filepath = self.get_default_node_path()
           ^
SyntaxError: invalid syntax
Traceback (most recent call last):
  File "phantom.py", line 15, in main
    import main
  File "src/main.py", line 6, in <module>
    from Phantom import Phantom_Db
  File "src/Phantom/Phantom_Db.py", line 5, in <module>
    class PhantomDb(object):
  File "src/Phantom/Phantom_Db.py", line 7, in PhantomDb
    self.conn_phantom = sqlite3.connect('src/Phantom/phantom.db')
NameError: name 'self' is not defined
Traceback (most recent call last):
  File "phantom.py", line 15, in main
    import main
  File "src/main.py", line 6, in <module>
    from Phantom import Phantom_Db
  File "src/Phantom/Phantom_Db.py", line 8
    self. = self.conn_phantom.cursor()
          ^
SyntaxError: invalid syntax
Traceback (most recent call last):
  File "phantom.py", line 15, in main
    import main
  File "src/main.py", line 6, in <module>
    from Phantom import Phantom_Db
  File "src/Phantom/Phantom_Db.py", line 5, in <module>
    class PhantomDb(object):
  File "src/Phantom/Phantom_Db.py", line 7, in PhantomDb
    self.conn_phantom = sqlite3.connect('src/Phantom/phantom.db')
NameError: name 'self' is not defined
